Workbook

Sheet ACT_school_suppressed
A1: School_ID | B1: SCHOOL_NAME | C1: City | D1: DISTRICT_NAME | E1: Subgroup | F1: Valid Tests | G1: Participation Rate | H1: Average English Score | I1: Average Math Score | J1: Average Reading Score | K1: Average Science Score | L1: Average Composite Score | M1: Number Scoring 21 or Higher | N1: Number Scoring Below 19 | O1: Average Composite At Least 20 | P1: All Areas At Least 20
A2: 10_2 | B2: =VLOOKUP(A2,schools!A2:B1750,2,FALSE) -> Anderson County High School | C2: =VLOOKUP(A2,schools!A2:F1750,5,FALSE) -> Clinton | D2: Anderson County | E2: All Students | F2: 239 | G2: 100 | H2: 19.1 | I2: 19.2 | J2: 20 | K2: 20.1 | L2: 19.7 | M2: 99 | N2: 103 | O2: =IFERROR(VLOOKUP(L2,$Q$2:$S$4,3,TRUE), "Score Not Available") -> Below 20 | P2: =IFERROR(IF(MIN(H2,I2,J2,K2)>20,"All at least 20", "Not all at least 20"),"Scores Not Available") -> Not all at least 20 | Q2: 0 | R2: 0-19 | S2: Below 20
A3: 10_25 | B3: =VLOOKUP(A3,schools!A3:B1751,2,FALSE) -> Clinton High School | C3: =VLOOKUP(A3,schools!A3:F1751,5,FALSE) -> Clinton | D3: Anderson County | E3: All Students | F3: 266 | G3: 95 | H3: 18.5 | I3: 18.6 | J3: 19.7 | K3: 19.4 | L3: 19.1 | M3: 92 | N3: 146 | O3: =IFERROR(VLOOKUP(L3,$Q$2:$S$4,3,TRUE), "Score Not Available") -> Below 20 | P3: =IFERROR(IF(MIN(H3,I3,J3,K3)>20,"All at least 20", "Not all at least 20"),"Scores Not Available") -> Not all at least 20 | Q3: 20 | R3: 20+ | S3: At least 20
A4: 12_35 | B4: =VLOOKUP(A4,schools!A4:B1752,2,FALSE) -> Oak Ridge High School | C4: =VLOOKUP(A4,schools!A4:F1752,5,FALSE) -> Oak Ridge | D4: Oak Ridge | E4: All Students | F4: 277 | G4: 100 | H4: 23.5 | I4: 22.1 | J4: 24.1 | K4: 22.9 | L4: 23.3 | M4: 182 | N4: 64 | O4: =IFERROR(VLOOKUP(L4,$Q$2:$S$4,3,TRUE), "Score Not Available") -> At least 20 | P4: =IFERROR(IF(MIN(H4,I4,J4,K4)>20,"All at least 20", "Not all at least 20"),"Scores Not Available") -> All at least 20 | R4: Blanks | S4: Blank Value | T4: It is being considered as Below 20
A5: 20_13 | B5: =VLOOKUP(A5,schools!A5:B1753,2,FALSE) -> Cascade High School | C5: =VLOOKUP(A5,schools!A5:F1753,5,FALSE) -> Wartrace | D5: Bedford County | E5: All Students | F5: 112 | G5: 99 | H5: 20.3 | I5: 19.9 | J5: 21.9 | K5: 20.9 | L5: 20.9 | M5: 58 | N5: 35 | O5: =IFERROR(VLOOKUP(L5,$Q$2:$S$4,3,TRUE), "Score Not Available") -> At least 20 | P5: =IFERROR(IF(MIN(H5,I5,J5,K5)>20,"All at least 20", "Not all at least 20"),"Scores Not Available") -> Not all at least 20
A6: 20_20 | B6: =VLOOKUP(A6,schools!A6:B1754,2,FALSE) -> Shelbyville Central High School | C6: =VLOOKUP(A6,schools!A6:F1754,5,FALSE) -> Shelbyville | D6: Bedford County | E6: All Students | F6: 296 | G6: 99 | H6: 17.8 | I6: 18.5 | J6: 19.2 | K6: 19.2 | L6: 18.9 | M6: 89 | N6: 166 | O6: =IFERROR(VLOOKUP(L6,$Q$2:$S$4,3,TRUE), "Score Not Available") -> Below 20 | P6: =IFERROR(IF(MIN(H6,I6,J6,K6)>20,"All at least 20", "Not all at least 20"),"Scores Not Available") -> Not all at least 20
A7: 20_35 | B7: =VLOOKUP(A7,schools!A7:B1755,2,FALSE) -> Community High School | C7: =VLOOKUP(A7,schools!A7:F1755,5,FALSE) -> Unionville | D7: Bedford County | E7: All Students | F7: 102 | G7: 99 | H7: 19.5 | I7: 18.5 | J7: 20.7 | K7: 20.6 | L7: 20 | M7: 36 | N7: 40 | O7: =IFERROR(VLOOKUP(L7,$Q$2:$S$4,3,TRUE), "Score Not Available") -> At least 20 | P7: =IFERROR(IF(MIN(H7,I7,J7,K7)>20,"All at least 20", "Not all at least 20"),"Scores Not Available") -> Not all at least 20
A8: 30_10 | B8: =VLOOKUP(A8,schools!A8:B1756,2,FALSE) -> Big Sandy School | C8: =VLOOKUP(A8,schools!A8:F1756,5,FALSE) -> Big Sandy | D8: Benton County | E8: All Students | F8: 21 | G8: 95 | H8: 17.8 | I8: 18.7 | J8: 20.4 | K8: 20.5 | L8: 19.5 | M8: 10 | N8: 8 | O8: =IFERROR(VLOOKUP(L8,$Q$2:$S$4,3,TRUE), "Score Not Available") -> Below 20 | P8: =IFERROR(IF(MIN(H8,I8,J8,K8)>20,"All at least 20", "Not all at least 20"),"Scores Not Available") -> Not all at least 20
A9: 30_25 | B9: =VLOOKUP(A9,schools!A9:B1757,2,FALSE) -> Camden Central High School | C9: =VLOOKUP(A9,schools!A9:F1757,5,FALSE) -> Camden | D9: Benton County | E9: All Students | F9: 136 | G9: 95 | H9: 20 | I9: 19.4 | J9: 20.5 | K9: 20.2 | L9: 20.2 | M9: 63 | N9: 55 | O9: =IFERROR(VLOOKUP(L9,$Q$2:$S$4,3,TRUE), "Score Not Available") -> At least 20 | P9: =IFERROR(IF(MIN(H9,I9,J9,K9)>20,"All at least 20", "Not all at least 20"),"Scores Not Available") -> Not all at least 20
A10: 40_5 | B10: =VLOOKUP(A10,schools!A10:B1758,2,FALSE) -> Bledsoe County High School | C10: =VLOOKUP(A10,schools!A10:F1758,5,FALSE) -> Pikeville | D10: Bledsoe County | E10: All Students | F10: 124 | G10: 98 | H10: 17.8 | I10: 19.3 | J10: 19.1 | K10: 19.3 | L10: 19 | M10: 39 | N10: 62 | O10: =IFERROR(VLOOKUP(L10,$Q$2:$S$4,3,TRUE), "Score Not Available") -> Below 20 | P10: =IFERROR(IF(MIN(H10,I10,J10,K10)>20,"All at least 20", "Not all at least 20"),"Scores Not Available") -> Not all at least 20
A11: 50_63 | B11: =VLOOKUP(A11,schools!A11:B1759,2,FALSE) -> Heritage High School | C11: =VLOOKUP(A11,schools!A11:F1759,5,FALSE) -> Maryville | D11: Blount County | E11: All Students | F11: 348 | G11: 96 | H11: 18.4 | I11: 18.7 | J11: 19.1 | K11: 18.8 | L11: 18.9 | M11: 115 | N11: 171 | O11: =IFERROR(VLOOKUP(L11,$Q$2:$S$4,3,TRUE), "Score Not Available") -> Below 20 | P11: =IFERROR(IF(MIN(H11,I11,J11,K11)>20,"All at least 20", "Not all at least 20"),"Scores Not Available") -> Not all at least 20
A12: 50_155 | B12: =VLOOKUP(A12,schools!A12:B1760,2,FALSE) -> William Blount High School | C12: =VLOOKUP(A12,schools!A12:F1760,5,FALSE) -> Maryville | D12: Blount County | E12: All Students | F12: 381 | G12: 98 | H12: 19.5 | I12: 19.4 | J12: 20.2 | K12: 19.6 | L12: 19.8 | M12: 156 | N12: 180 | O12: =IFERROR(VLOOKUP(L12,$Q$2:$S$4,3,TRUE), "Score Not Available") -> Below 20 | P12: =IFERROR(IF(MIN(H12,I12,J12,K12)>20,"All at least 20", "Not all at least 20"),"Scores Not Available") -> Not all at least 20
A13: 51_10 | B13: =VLOOKUP(A13,schools!A13:B1761,2,FALSE) -> Alcoa High School | C13: =VLOOKUP(A13,schools!A13:F1761,5,FALSE) -> Alcoa | D13: Alcoa | E13: All Students | F13: 157 | G13: 99 | H13: 21.7 | I13: 20.4 | J13: 21.7 | K13: 20.8 | L13: 21.3 | M13: 87 | N13: 51 | O13: =IFERROR(VLOOKUP(L13,$Q$2:$S$4,3,TRUE), "Score Not Available") -> At least 20 | P13: =IFERROR(IF(MIN(H13,I13,J13,K13)>20,"All at least 20", "Not all at least 20"),"Scores Not Available") -> All at least 20
A14: 52_15 | B14: =VLOOKUP(A14,schools!A14:B1762,2,FALSE) -> Maryville High School | C14: =VLOOKUP(A14,schools!A14:F1762,5,FALSE) -> Maryville | D14: Maryville | E14: All Students | F14: 420 | G14: 99 | H14: 24.1 | I14: 23.5 | J14: 24.8 | K14: 24.1 | L14: 24.3 | M14: 301 | N14: 73 | O14: =IFERROR(VLOOKUP(L14,$Q$2:$S$4,3,TRUE), "Score Not Available") -> At least 20 | P14: =IFERROR(IF(MIN(H14,I14,J14,K14)>20,"All at least 20", "Not all at least 20"),"Scores Not Available") -> All at least 20
A15: 60_20 | B15: =VLOOKUP(A15,schools!A15:B1763,2,FALSE) -> Bradley Central High School | C15: =VLOOKUP(A15,schools!A15:F1763,5,FALSE) -> Cleveland | D15: Bradley County | E15: All Students | F15: 382 | G15: 100 | H15: 18.9 | I15: 18.5 | J15: 20.1 | K15: 19.9 | L15: 19.5 | M15: 147 | N15: 166 | O15: =IFERROR(VLOOKUP(L15,$Q$2:$S$4,3,TRUE), "Score Not Available") -> Below 20 | P15: =IFERROR(IF(MIN(H15,I15,J15,K15)>20,"All at least 20", "Not all at least 20"),"Scores Not Available") -> Not all at least 20
A16: 60_53 | B16: =VLOOKUP(A16,schools!A16:B1764,2,FALSE) -> North Cleveland GOAL Academy | C16: =VLOOKUP(A16,schools!A16:F1764,5,FALSE) -> Cleveland | D16: Bradley County | E16: All Students | F16: 27 | G16: 100 | H16: 13.8 | I16: 16.1 | J16: 15.2 | K16: 15 | L16: 15.1 | M16: ** | N16: ** | O16: =IFERROR(VLOOKUP(L16,$Q$2:$S$4,3,TRUE), "Score Not Available") -> Below 20 | P16: =IFERROR(IF(MIN(H16,I16,J16,K16)>20,"All at least 20", "Not all at least 20"),"Scores Not Available") -> Not all at least 20
A17: 60_78 | B17: =VLOOKUP(A17,schools!A17:B1765,2,FALSE) -> Walker Valley High School | C17: =VLOOKUP(A17,schools!A17:F1765,5,FALSE) -> Cleveland | D17: Bradley County | E17: All Students | F17: 336 | G17: 100 | H17: 22.1 | I17: 21 | J17: 22.8 | K17: 21.9 | L17: 22.1 | M17: 201 | N17: 91 | O17: =IFERROR(VLOOKUP(L17,$Q$2:$S$4,3,TRUE), "Score Not Available") -> At least 20 | P17: =IFERROR(IF(MIN(H17,I17,J17,K17)>20,"All at least 20", "Not all at least 20"),"Scores Not Available") -> All at least 20
A18: 60_105 | B18: =VLOOKUP(A18,schools!A18:B1766,2,FALSE) -> Bradley County Virtual School | C18: =VLOOKUP(A18,schools!A18:F1766,5,FALSE) -> Cleveland | D18: Bradley County | E18: All Students | F18: 9 | G18: * | H18: * | I18: * | J18: * | K18: * | L18: * | M18: * | N18: * | O18: =IFERROR(VLOOKUP(L18,$Q$2:$S$4,3,TRUE), "Score Not Available") -> Score Not Available | P18: =IFERROR(IF(MIN(H18,I18,J18,K18)>20,"All at least 20", "Not all at least 20"),"Scores Not Available") -> Not all at least 20
A19: 61_20 | B19: =VLOOKUP(A19,schools!A19:B1767,2,FALSE) -> Cleveland High | C19: =VLOOKUP(A19,schools!A19:F1767,5,FALSE) -> Cleveland | D19: Cleveland | E19: All Students | F19: 314 | G19: 96 | H19: 19.6 | I19: 19.6 | J19: 21.2 | K19: 20.7 | L19: 20.4 | M19: 141 | N19: 129 | O19: =IFERROR(VLOOKUP(L19,$Q$2:$S$4,3,TRUE), "Score Not Available") -> At least 20 | P19: =IFERROR(IF(MIN(H19,I19,J19,K19)>20,"All at least 20", "Not all at least 20"),"Scores Not Available") -> Not all at least 20
A20: 61_40 | B20: =VLOOKUP(A20,schools!A20:B1768,2,FALSE) -> F.I. Denning Center of Technology and Careers | C20: =VLOOKUP(A20,schools!A20:F1768,5,FALSE) -> Cleveland | D20: Cleveland | E20: All Students | F20: 35 | G20: 100 | H20: 14.6 | I20: 17 | J20: 15.2 | K20: 15.9 | L20: 15.9 | M20: 3 | N20: 29 | O20: =IFERROR(VLOOKUP(L20,$Q$2:$S$4,3,TRUE), "Score Not Available") -> Below 20 | P20: =IFERROR(IF(MIN(H20,I20,J20,K20)>20,"All at least 20", "Not all at least 20"),"Scores Not Available") -> Not all at least 20
A21: 70_3 | B21: =VLOOKUP(A21,schools!A21:B1769,2,FALSE) -> Campbell County Comprehensive High School | C21: =VLOOKUP(A21,schools!A21:F1769,5,FALSE) -> Jacksboro | D21: Campbell County | E21: All Students | F21: 285 | G21: 92 | H21: 17.5 | I21: 17.3 | J21: 19.3 | K21: 18.6 | L21: 18.3 | M21: 78 | N21: 160 | O21: =IFERROR(VLOOKUP(L21,$Q$2:$S$4,3,TRUE), "Score Not Available") -> Below 20 | P21: =IFERROR(IF(MIN(H21,I21,J21,K21)>20,"All at least 20", "Not all at least 20"),"Scores Not Available") -> Not all at least 20
A22: 70_75 | B22: =VLOOKUP(A22,schools!A22:B1770,2,FALSE) -> Jellico High School | C22: =VLOOKUP(A22,schools!A22:F1770,5,FALSE) -> Jellico | D22: Campbell County | E22: All Students | F22: 68 | G22: 97 | H22: 18.5 | I22: 17.7 | J22: 19.3 | K22: 18.9 | L22: 18.8 | M22: 20 | N22: 36 | O22: =IFERROR(VLOOKUP(L22,$Q$2:$S$4,3,TRUE), "Score Not Available") -> Below 20 | P22: =IFERROR(IF(MIN(H22,I22,J22,K22)>20,"All at least 20", "Not all at least 20"),"Scores Not Available") -> Not all at least 20
A23: 80_16 | B23: =VLOOKUP(A23,schools!A23:B1771,2,FALSE) -> Cannon County High School | C23: =VLOOKUP(A23,schools!A23:F1771,5,FALSE) -> Woodbury | D23: Cannon County | E23: All Students | F23: 105 | G23: 99 | H23: 18.5 | I23: 18.1 | J23: 19.3 | K23: 19.2 | L23: 18.9 | M23: 38 | N23: 52 | O23: =IFERROR(VLOOKUP(L23,$Q$2:$S$4,3,TRUE), "Score Not Available") -> Below 20 | P23: =IFERROR(IF(MIN(H23,I23,J23,K23)>20,"All at least 20", "Not all at least 20"),"Scores Not Available") -> Not all at least 20
A24: 92_10 | B24: =VLOOKUP(A24,schools!A24:B1772,2,FALSE) -> Central High School | C24: =VLOOKUP(A24,schools!A24:F1772,5,FALSE) -> Bruceton | D24: Hollow Rock - Bruceton | E24: All Students | F24: 40 | G24: 100 | H24: 18.4 | I24: 18.6 | J24: 18.9 | K24: 19.1 | L24: 18.9 | M24: 15 | N24: 18 | O24: =IFERROR(VLOOKUP(L24,$Q$2:$S$4,3,TRUE), "Score Not Available") -> Below 20 | P24: =IFERROR(IF(MIN(H24,I24,J24,K24)>20,"All at least 20", "Not all at least 20"),"Scores Not Available") -> Not all at least 20
A25: 93_10 | B25: =VLOOKUP(A25,schools!A25:B1773,2,FALSE) -> Huntingdon High School | C25: =VLOOKUP(A25,schools!A25:F1773,5,FALSE) -> Huntingdon | D25: Huntingdon Special School District | E25: All Students | F25: 73 | G25: 100 | H25: 19.4 | I25: 18.8 | J25: 20.2 | K25: 20 | L25: 19.8 | M25: 30 | N25: 34 | O25: =IFERROR(VLOOKUP(L25,$Q$2:$S$4,3,TRUE), "Score Not Available") -> Below 20 | P25: =IFERROR(IF(MIN(H25,I25,J25,K25)>20,"All at least 20", "Not all at least 20"),"Scores Not Available") -> Not all at least 20
A26: 94_10 | B26: =VLOOKUP(A26,schools!A26:B1774,2,FALSE) -> McKenzie High School | C26: =VLOOKUP(A26,schools!A26:F1774,5,FALSE) -> McKenzie | D26: McKenzie | E26: All Students | F26: 105 | G26: 98 | H26: 20.7 | I26: 19.8 | J26: 22 | K26: 21.8 | L26: 21.2 | M26: 56 | N26: 36 | O26: =IFERROR(VLOOKUP(L26,$Q$2:$S$4,3,TRUE), "Score Not Available") -> At least 20 | P26: =IFERROR(IF(MIN(H26,I26,J26,K26)>20,"All at least 20", "Not all at least 20"),"Scores Not Available") -> Not all at least 20
A27: 95_5 | B27: =VLOOKUP(A27,schools!A27:B1775,2,FALSE) -> Clarksburg School | C27: =VLOOKUP(A27,schools!A27:F1775,5,FALSE) -> Clarksburg | D27: South Carroll | E27: All Students | F27: 25 | G27: 100 | H27: 18.5 | I27: 19 | J27: 19.5 | K27: 20.1 | L27: 19.4 | M27: 11 | N27: 12 | O27: =IFERROR(VLOOKUP(L27,$Q$2:$S$4,3,TRUE), "Score Not Available") -> Below 20 | P27: =IFERROR(IF(MIN(H27,I27,J27,K27)>20,"All at least 20", "Not all at least 20"),"Scores Not Available") -> Not all at least 20
A28: 97_5 | B28: =VLOOKUP(A28,schools!A28:B1776,2,FALSE) -> West Carroll Junior/Senior High School | C28: =VLOOKUP(A28,schools!A28:F1776,5,FALSE) -> Atwood | D28: West Carroll Sp Dist | E28: All Students | F28: 57 | G28: 100 | H28: 19.3 | I28: 18.3 | J28: 19.9 | K28: 19.7 | L28: 19.4 | M28: 23 | N28: 25 | O28: =IFERROR(VLOOKUP(L28,$Q$2:$S$4,3,TRUE), "Score Not Available") -> Below 20 | P28: =IFERROR(IF(MIN(H28,I28,J28,K28)>20,"All at least 20", "Not all at least 20"),"Scores Not Available") -> Not all at least 20
A29: 100_15 | B29: =VLOOKUP(A29,schools!A29:B1777,2,FALSE) -> Cloudland High School | C29: =VLOOKUP(A29,schools!A29:F1777,5,FALSE) -> Roan Mountain | D29: Carter County | E29: All Students | F29: 40 | G29: 98 | H29: 16 | I29: 17.2 | J29: 17.2 | K29: 18.1 | L29: 17.3 | M29: 8 | N29: 25 | O29: =IFERROR(VLOOKUP(L29,$Q$2:$S$4,3,TRUE), "Score Not Available") -> Below 20 | P29: =IFERROR(IF(MIN(H29,I29,J29,K29)>20,"All at least 20", "Not all at least 20"),"Scores Not Available") -> Not all at least 20
A30: 100_30 | B30: =VLOOKUP(A30,schools!A30:B1778,2,FALSE) -> Hampton High School | C30: =VLOOKUP(A30,schools!A30:F1778,5,FALSE) -> Hampton | D30: Carter County | E30: All Students | F30: 92 | G30: 88 | H30: 18.6 | I30: 18.1 | J30: 20.4 | K30: 20 | L30: 19.1 | M30: 28 | N30: 41 | O30: =IFERROR(VLOOKUP(L30,$Q$2:$S$4,3,TRUE), "Score Not Available") -> Below 20 | P30: =IFERROR(IF(MIN(H30,I30,J30,K30)>20,"All at least 20", "Not all at least 20"),"Scores Not Available") -> Not all at least 20
... A47: 180_79 | B47: =VLOOKUP(A47,schools!A47:B1795,2,FALSE) -> Stone Memorial High School | C47: =VLOOKUP(A47,schools!A47:F1795,5,FALSE) -> Crossville | D47: Cumberland County | E47: All Students | F47: 223 | G47: 97 | H47: 20.9 | I47: 20.8 | J47: 21.8 | K47: 21.4 | L47: 21.4 | M47: 123 | N47: 68 | O47: =IFERROR(VLOOKUP(L47,$Q$2:$S$4,3,TRUE), "Score Not Available") -> At least 20 | P47: =IFERROR(IF(MIN(H47,I47,J47,K47)>20,"All at least 20", "Not all at least 20"),"Scores Not Available") -> All at least 20
A48: 180_85 | B48: =VLOOKUP(A48,schools!A48:B1796,2,FALSE) -> The Phoenix School | C48: =VLOOKUP(A48,schools!A48:F1796,5,FALSE) -> Crossville | D48: Cumberland County | E48: All Students | F48: 67 | G48: 93 | H48: 14 | I48: 16 | J48: 15.5 | K48: 15.2 | L48: 15.3 | M48: ** | N48: ** | O48: =IFERROR(VLOOKUP(L48,$Q$2:$S$4,3,TRUE), "Score Not Available") -> Below 20 | P48: =IFERROR(IF(MIN(H48,I48,J48,K48)>20,"All at least 20", "Not all at least 20"),"Scores Not Available") -> Not all at least 20
A49: 190_3 | B49: =VLOOKUP(A49,schools!A49:B1797,2,FALSE) -> MNPS Virtual School | C49: =VLOOKUP(A49,schools!A49:F1797,5,FALSE) -> Nashville | D49: Davidson County | E49: All Students | F49: 18 | G49: 95 | H49: 22.7 | I49: 20.9 | J49: 22.4 | K49: 22.1 | L49: 22.2 | M49: 10 | N49: 5 | O49: =IFERROR(VLOOKUP(L49,$Q$2:$S$4,3,TRUE), "Score Not Available") -> At least 20 | P49: =IFERROR(IF(MIN(H49,I49,J49,K49)>20,"All at least 20", "Not all at least 20"),"Scores Not Available") -> All at least 20
A50: 190_20 | B50: =VLOOKUP(A50,schools!A50:B1798,2,FALSE) -> Antioch High School | C50: =VLOOKUP(A50,schools!A50:F1798,5,FALSE) -> Antioch | D50: Davidson County | E50: All Students | F50: 435 | G50: 96 | H50: 16.5 | I50: 17.6 | J50: 18.1 | K50: 18 | L50: 17.7 | M50: 94 | N50: 276 | O50: =IFERROR(VLOOKUP(L50,$Q$2:$S$4,3,TRUE), "Score Not Available") -> Below 20 | P50: =IFERROR(IF(MIN(H50,I50,J50,K50)>20,"All at least 20", "Not all at least 20"),"Scores Not Available") -> Not all at least 20
A51: 190_53 | B51: =VLOOKUP(A51,schools!A51:B1799,2,FALSE) -> Nashville Big Picture High School | C51: =VLOOKUP(A51,schools!A51:F1799,5,FALSE) -> Nashville | D51: Davidson County | E51: All Students | F51: 25 | G51: 100 | H51: 20.1 | I51: 17.3 | J51: 20.4 | K51: 20 | L51: 19.6 | M51: 7 | N51: 12 | O51: =IFERROR(VLOOKUP(L51,$Q$2:$S$4,3,TRUE), "Score Not Available") -> Below 20 | P51: =IFERROR(IF(MIN(H51,I51,J51,K51)>20,"All at least 20", "Not all at least 20"),"Scores Not Available") -> Not all at least 20
A52: 190_77 | B52: =VLOOKUP(A52,schools!A52:B1800,2,FALSE) -> Cane Ridge High School | C52: =VLOOKUP(A52,schools!A52:F1800,5,FALSE) -> Antioch | D52: Davidson County | E52: All Students | F52: 391 | G52: 96 | H52: 16.3 | I52: 17.3 | J52: 17.6 | K52: 17.7 | L52: 17.4 | M52: 79 | N52: 266 | O52: =IFERROR(VLOOKUP(L52,$Q$2:$S$4,3,TRUE), "Score Not Available") -> Below 20 | P52: =IFERROR(IF(MIN(H52,I52,J52,K52)>20,"All at least 20", "Not all at least 20"),"Scores Not Available") -> Not all at least 20
A53: 190_203 | B53: =VLOOKUP(A53,schools!A53:B1801,2,FALSE) -> East Nashville Magnet High School | C53: =VLOOKUP(A53,schools!A53:F1801,5,FALSE) -> Nashville | D53: Davidson County | E53: All Students | F53: 159 | G53: 99 | H53: 17.5 | I53: 17.8 | J53: 18.8 | K53: 18.4 | L53: 18.3 | M53: 33 | N53: 93 | O53: =IFERROR(VLOOKUP(L53,$Q$2:$S$4,3,TRUE), "Score Not Available") -> Below 20 | P53: =IFERROR(IF(MIN(H53,I53,J53,K53)>20,"All at least 20", "Not all at least 20"),"Scores Not Available") -> Not all at least 20
A54: 190_245 | B54: =VLOOKUP(A54,schools!A54:B1802,2,FALSE) -> Glencliff High School | C54: =VLOOKUP(A54,schools!A54:F1802,5,FALSE) -> Nashville | D54: Davidson County | E54: All Students | F54: 262 | G54: 97 | H54: 15.5 | I54: 16.8 | J54: 17.3 | K54: 17.3 | L54: 16.8 | M54: 45 | N54: 179 | O54: =IFERROR(VLOOKUP(L54,$Q$2:$S$4,3,TRUE), "Score Not Available") -> Below 20 | P54: =IFERROR(IF(MIN(H54,I54,J54,K54)>20,"All at least 20", "Not all at least 20"),"Scores Not Available") -> Not all at least 20
A55: 190_302 | B55: =VLOOKUP(A55,schools!A55:B1803,2,FALSE) -> Harris-Hillman Special Education | C55: =VLOOKUP(A55,schools!A55:F1803,5,FALSE) -> Nashville | D55: Davidson County | E55: All Students | F55: 0 | G55: 0 | M55: 0 | N55: 0 | O55: =IFERROR(VLOOKUP(L55,$Q$2:$S$4,3,TRUE), "Score Not Available") -> Below 20 | P55: =IFERROR(IF(MIN(H55,I55,J55,K55)>20,"All at least 20", "Not all at least 20"),"Scores Not Available") -> Not all at least 20
A56: 190_335 | B56: =VLOOKUP(A56,schools!A56:B1804,2,FALSE) -> Hillsboro High | C56: =VLOOKUP(A56,schools!A56:F1804,5,FALSE) -> Nashville | D56: Davidson County | E56: All Students | F56: 233 | G56: 97 | H56: 20.6 | I56: 19.2 | J56: 21.9 | K56: 20.5 | L56: 20.7 | M56: 99 | N56: 89 | O56: =IFERROR(VLOOKUP(L56,$Q$2:$S$4,3,TRUE), "Score Not Available") -> At least 20 | P56: =IFERROR(IF(MIN(H56,I56,J56,K56)>20,"All at least 20", "Not all at least 20"),"Scores Not Available") -> Not all at least 20
...

Sheet schools
A1: School_ID | B1: SCHOOL_NAME | C1: SCHOOL_TYPE | D1: ADDRESS | E1: CITY | F1: STATE | G1: ZIP | H1: CHARTER
A2: 10_2 | B2: Anderson County High School | C2: Public | D2: 130 Maverick CIR | E2: Clinton | F2: TN | G2: 37716 | H2: N
A3: 10_5 | B3: Andersonville Elementary | C3: Public | D3: 1951 Mountain RD | E3: Andersonville | F3: TN | G3: 37705 | H3: N
A4: 10_10 | B4: Briceville Elementary | C4: Public | D4: 103 Slatestone RD | E4: Briceville | F4: TN | G4: 37710 | H4: N
A5: 10_15 | B5: Claxton Elementary | C5: Public | D5: 2218 Clinton HWY | E5: Powell | F5: TN | G5: 37849 | H5: N
A6: 10_20 | B6: Clinton Middle School | C6: Public | D6: 110 N Hicks ST | E6: Clinton | F6: TN | G6: 37716 | H6: N
A7: 10_25 | B7: Clinton High School | C7: Public | D7: 425 Dragon DR | E7: Clinton | F7: TN | G7: 37716 | H7: N
A8: 10_35 | B8: Dutch Valley Elementary | C8: Public | D8: 1044 Old Dutch Valley RD | E8: Clinton | F8: TN | G8: 37716 | H8: N
A9: 10_40 | B9: Fairview Elementary | C9: Public | D9: 6715 Hickory Valley RD | E9: Heiskell | F9: TN | G9: 37754 | H9: N
A10: 10_46 | B10: Grand Oaks Elementary | C10: Public | D10: 1033 Oliver Springs HWY | E10: Clinton | F10: TN | G10: 37716 | H10: N
A11: 10_50 | B11: Lake City Elementary | C11: Public | D11: 402 Lindsay ST | E11: Lake City | F11: TN | G11: 37769 | H11: N
A12: 10_55 | B12: Lake City Middle School | C12: Public | D12: 1132 S Main ST | E12: Lake City | F12: TN | G12: 37769 | H12: N
A13: 10_70 | B13: Norris Elementary | C13: Public | D13: 42 East Circle DR | E13: Norris | F13: TN | G13: 37828 | H13: N
... A1750: 986_8005 | B1750: Bluff City High School | C1750: Public Charter | D1750: 4100 Ross RD | E1750: Memphis | F1750: TN | G1750: 38115 | H1750: Y

Sheet districts
A1: District Name | B1: District_Number
A2: Anderson County | B2: 10
A3: Oak Ridge | B3: 12
A4: Bedford County | B4: 20
A5: Benton County | B5: 30
A6: Bledsoe County | B6: 40
A7: Blount County | B7: 50
A8: Alcoa | B8: 51
A9: Maryville | B9: 52
A10: Bradley County | B10: 60
A11: Cleveland | B11: 61
A12: Campbell County | B12: 70
A13: Cannon County | B13: 80
... A130: Achievement School District | B130: 985

Sheet answers
A1: Question 2
A2: Largest Average Composite Score: | B2: =MAX(ACT_school_suppressed!$L:$L) -> 30.7 | C2: =MAX(ACT_school_suppressed!$L:$L) -> 30.7
A3: School: | B3: =_xlfn.XLOOKUP(B2,ACT_school_suppressed!$L:$L,ACT_school_suppressed!$B:$B,"Not Found",0) -> Central Magnet School | C3: =_xlfn.XLOOKUP(C2,ACT_school_suppressed!$L:$L,ACT_school_suppressed!$B:$B,"Not Found",0) -> Central Magnet School | D3: There are 2 schools, I do not know how to show the next one
D4: {=_xlfn._xlws.FILTER(ACT_school_suppressed!B:B,ACT_school_suppressed!L:L=B2)} -> Central Magnet School
A5: Smallest Average Composite Score: | B5: =MIN(ACT_school_suppressed!L:L) -> 13.6 | D5: Merrol Hyde Magnet School
A6: School: | B6: =_xlfn.XLOOKUP(B5,ACT_school_suppressed!L:L,ACT_school_suppressed!B:B,"Not Found",0) -> Tennessee High School For Deaf
A8: Question 3
A9: City | B9: Number of Valid Tests | C9: Number Scoring 21 or Over | D9: Percent Scoring 21 or Over
A10: Nashville | B10: =SUMIF(ACT_school_suppressed!$C$1:$C$368,answers!A10,ACT_school_suppressed!$F$1:$F$368) -> 3327 | C10: =SUMIF(ACT_school_suppressed!$C$1:$C$368,answers!A10,ACT_school_suppressed!$M$1:$M$368) -> 769 | D10: =_xlfn.PERCENTOF(C10,B10) -> 0.23113916
A11: Memphis | B11: =SUMIF(ACT_school_suppressed!$C$1:$C$368,answers!A11,ACT_school_suppressed!$F$1:$F$368) -> 5391 | C11: =SUMIF(ACT_school_suppressed!$C$1:$C$368,answers!A11,ACT_school_suppressed!$M$1:$M$368) -> 991 | D11: =_xlfn.PERCENTOF(C11,B11) -> 0.18382489
A12: Knoxville | B12: =SUMIF(ACT_school_suppressed!$C$1:$C$368,answers!A12,ACT_school_suppressed!$F$1:$F$368) -> 3242 | C12: =SUMIF(ACT_school_suppressed!$C$1:$C$368,answers!A12,ACT_school_suppressed!$M$1:$M$368) -> 1769 | D12: =_xlfn.PERCENTOF(C12,B12) -> 0.54565083
A13: Chattanooga | B13: =SUMIF(ACT_school_suppressed!$C$1:$C$368,answers!A13,ACT_school_suppressed!$F$1:$F$368) -> 1071 | C13: =SUMIF(ACT_school_suppressed!$C$1:$C$368,answers!A13,ACT_school_suppressed!$M$1:$M$368) -> 303 | D13: =_xlfn.PERCENTOF(C13,B13) -> 0.28291317

Sheet Davidson County
A1: School_ID | B1: SCHOOL_NAME | C1: City | D1: DISTRICT_NAME | E1: Subgroup | F1: Valid Tests | G1: Participation Rate | H1: Average English Score | I1: Average Math Score | J1: Average Reading Score | K1: Average Science Score | L1: Average Composite Score | M1: Number Scoring 21 or Higher | N1: Number Scoring Below 19 | O1: Average Composite At Least 20 | P1: All Areas At Least 20
A2: 190_3 | B2: MNPS Virtual School | C2: Nashville | D2: Davidson County | E2: All Students | F2: 18 | G2: 95 | H2: 22.7 | I2: 20.9 | J2: 22.4 | K2: 22.1 | L2: 22.2 | M2: 10 | N2: 5 | O2: 0 | P2: 0
A3: 190_20 | B3: Antioch High School | C3: Antioch | D3: Davidson County | E3: All Students | F3: 435 | G3: 96 | H3: 16.5 | I3: 17.6 | J3: 18.1 | K3: 18 | L3: 17.7 | M3: 94 | N3: 276 | O3: 0 | P3: 0
A4: 190_53 | B4: Nashville Big Picture High School | C4: Nashville | D4: Davidson County | E4: All Students | F4: 25 | G4: 100 | H4: 20.1 | I4: 17.3 | J4: 20.4 | K4: 20 | L4: 19.6 | M4: 7 | N4: 12 | O4: 0 | P4: 0
A5: 190_77 | B5: Cane Ridge High School | C5: Antioch | D5: Davidson County | E5: All Students | F5: 391 | G5: 96 | H5: 16.3 | I5: 17.3 | J5: 17.6 | K5: 17.7 | L5: 17.4 | M5: 79 | N5: 266 | O5: 0 | P5: 0
A6: 190_203 | B6: East Nashville Magnet High School | C6: Nashville | D6: Davidson County | E6: All Students | F6: 159 | G6: 99 | H6: 17.5 | I6: 17.8 | J6: 18.8 | K6: 18.4 | L6: 18.3 | M6: 33 | N6: 93 | O6: 0 | P6: 0
A7: 190_245 | B7: Glencliff High School | C7: Nashville | D7: Davidson County | E7: All Students | F7: 262 | G7: 97 | H7: 15.5 | I7: 16.8 | J7: 17.3 | K7: 17.3 | L7: 16.8 | M7: 45 | N7: 179 | O7: 0 | P7: 0
A8: 190_302 | B8: Harris-Hillman Special Education | C8: Nashville | D8: Davidson County | E8: All Students | F8: 0 | G8: 0 | H8: 0 | I8: 0 | J8: 0 | K8: 0 | L8: 0 | M8: 0 | N8: 0 | O8: 0 | P8: 0
A9: 190_335 | B9: Hillsboro High | C9: Nashville | D9: Davidson County | E9: All Students | F9: 233 | G9: 97 | H9: 20.6 | I9: 19.2 | J9: 21.9 | K9: 20.5 | L9: 20.7 | M9: 99 | N9: 89 | O9: 0 | P9: 0
A10: 190_340 | B10: Hillwood High | C10: Nashville | D10: Davidson County | E10: All Students | F10: 216 | G10: 100 | H10: 19.1 | I10: 19 | J10: 20.3 | K10: 19.7 | L10: 19.7 | M10: 88 | N10: 93 | O10: 0 | P10: 0
A11: 190_355 | B11: Hume - Fogg High | C11: Nashville | D11: Davidson County | E11: All Students | F11: 212 | G11: 100 | H11: 28.9 | I11: 26.6 | J11: 29.6 | K11: 27.9 | L11: 28.5 | M11: ** | N11: ** | O11: 0 | P11: 0
A12: 190_358 | B12: Hunters Lane High | C12: Nashville | D12: Davidson County | E12: All Students | F12: 325 | G12: 86 | H12: 15.1 | I12: 16.3 | J12: 16.6 | K12: 16.3 | L12: 16.2 | M12: 43 | N12: 250 | O12: 0 | P12: 0
A13: 190_395 | B13: John Overton High | C13: Nashville | D13: Davidson County | E13: All Students | F13: 431 | G13: 96 | H13: 17.4 | I13: 17.9 | J13: 18.7 | K13: 18.5 | L13: 18.3 | M13: 120 | N13: 255 | O13: 0 | P13: 0
A14: 190_437 | B14: Middle College High | C14: Nashville | D14: Davidson County | E14: All Students | F14: 34 | G14: 92 | H14: 21.7 | I14: 20.2 | J14: 23 | K14: 21.5 | L14: 21.8 | M14: 18 | N14: 9 | O14: 0 | P14: 0
A15: 190_443 | B15: Cora Howe School | C15: Nashville | D15: Davidson County | E15: All Students | F15: 6 | G15: * | H15: * | I15: * | J15: * | K15: * | L15: * | M15: * | N15: * | O15: 0 | P15: 0
A16: 190_445 | B16: Maplewood High | C16: Nashville | D16: Davidson County | E16: All Students | F16: 178 | G16: 98 | H16: 14.3 | I16: 16 | J16: 15.5 | K16: 15.9 | L16: 15.6 | M16: 15 | N16: 151 | O16: 0 | P16: 0
A17: 190_456 | B17: Martin Luther King Jr School | C17: Nashville | D17: Davidson County | E17: All Students | F17: 240 | G17: 100 | H17: 27.6 | I17: 26.8 | J17: 28.1 | K17: 26.6 | L17: 27.4 | M17: ** | N17: ** | O17: 0 | P17: 0
A18: 190_470 | B18: McGavock High | C18: Nashville | D18: Davidson County | E18: All Students | F18: 370 | G18: 89 | H18: 18.7 | I18: 18.1 | J18: 20.4 | K18: 19.5 | L18: 19.3 | M18: 133 | N18: 183 | O18: 0 | P18: 0
A19: 190_512 | B19: Nashville School Of The Arts | C19: Nashville | D19: Davidson County | E19: All Students | F19: 120 | G19: 96 | H19: 22.1 | I19: 18.9 | J19: 22.4 | K19: 20.7 | L19: 21.1 | M19: 59 | N19: 33 | O19: 0 | P19: 0
A20: 190_555 | B20: Pearl-Cohn High | C20: Nashville | D20: Davidson County | E20: All Students | F20: 140 | G20: 99 | H20: 14.3 | I20: 15.9 | J20: 15.6 | K20: 16.1 | L20: 15.6 | M20: 10 | N20: 121 | O20: 0 | P20: 0
A21: 190_612 | B21: The Academy at Opry Mills | C21: Nashville | D21: Davidson County | E21: All Students | F21: 45 | G21: 88 | H21: 16.5 | I21: 17.2 | J21: 17.3 | K21: 17.5 | L21: 17.2 | M21: 9 | N21: 32 | O21: 0 | P21: 0
A22: 190_614 | B22: The Academy at Old Cockrill | C22: Nashville | D22: Davidson County | E22: All Students | F22: 56 | G22: 79 | H22: 16.6 | I22: 17.2 | J22: 18.3 | K22: 17.6 | L22: 17.4 | M22: 15 | N22: 36 | O22: 0 | P22: 0
A23: 190_620 | B23: Stratford STEM Magnet School | C23: Nashville | D23: Davidson County | E23: All Students | F23: 152 | G23: 91 | H23: 15.1 | I23: 16.2 | J23: 16.6 | K23: 16.8 | L23: 16.2 | M23: 16 | N23: 112 | O23: 0 | P23: 0
A24: 190_704 | B24: Whites Creek High | C24: Whites Creek | D24: Davidson County | E24: All Students | F24: 139 | G24: 97 | H24: 14.7 | I24: 16.1 | J24: 16.1 | K24: 16.6 | L24: 16 | M24: 13 | N24: 109 | O24: 0 | P24: 0
A25: 190_720 | B25: The Academy at Hickory Hollow | C25: Antioch | D25: Davidson County | E25: All Students | F25: 77 | G25: 85 | H25: 14.2 | I25: 15.9 | J25: 15.4 | K25: 15.3 | L25: 15.4 | M25: 7 | N25: 64 | O25: 0 | P25: 0
A26: 190_740 | B26: Johnson Alternative Learning Center | C26: Nashville | D26: Davidson County | E26: All Students | F26: 1 | G26: * | H26: * | I26: * | J26: * | K26: * | L26: * | M26: * | N26: * | O26: 0 | P26: 0
A27: 190_8003 | B27: Lead Academy | C27: Nashville | D27: Davidson County | E27: All Students | F27: 47 | G27: 100 | H27: 18.3 | I27: 17.9 | J27: 18.6 | K27: 19.7 | L27: 18.7 | M27: 14 | N27: 25 | O27: 0 | P27: 0
A28: 190_8011 | B28: KIPP Nashville Collegiate High School | C28: Nashville | D28: Davidson County | E28: All Students | F28: 55 | G28: 100 | H28: 22.5 | I28: 23.1 | J28: 22.3 | K28: 20.7 | L28: 22.3 | M28: 35 | N28: 11 | O28: 0 | P28: 0

Sheet 5_Pivot Table_No._of_Schools
A3: Row Labels | B3: Count of SCHOOL_NAME | D3: Shelby County has the most schools
A4: Shelby County | B4: 41
A5: Davidson County | B5: 27
A6: Hamilton County | B6: 22
A7: Knox County | B7: 17
A8: Sumner County | B8: 10
A9: Rutherford County | B9: 10
A10: Grand Total | B10: 127

Sheet 6c_Avg.of Scores
A3: Row Labels | B3: Average of Valid Tests
A4: At least 20 | B4: 214.02 | F4: Observation : It is averaging out the scores, if the School Name is same inspite of the different City/ District
A5: Below 20 | B5: 151.75
A6: Score Not Available | B6: 4.9230769
A7: Grand Total | B7: 172
